<?xml version="1.0" ?>
<!-- =================================================================================== -->
<!-- |    This document was autogenerated by xacro from myrobot.xacro                  | -->
<!-- |    EDITING THIS FILE BY HAND IS NOT RECOMMENDED                                 | -->
<!-- =================================================================================== -->
<robot name="basic_robot">
  <param command="xacro '/home/nayal/nasa_ws/src/new_robot_urdf/urdf/myrobot.urdf.xacro'" name="robot_description"/>
  <!--colors-->
  <material name="blue">
    <color rgba=" 0 0 0.8 1"/>
  </material>
  <!--All Xacro Macros-->
  <link name="base_link">
    <visual>
      <origin xyz="0 0 0.1"/>
      <geometry>
        <box size="1.0 1.0 0.1"/>
      </geometry>
    </visual>
    <collision>
      <origin xyz="0 0 0.1"/>
      <geometry>
        <box size="1.0 1.0 0.1"/>
      </geometry>
    </collision>
    <inertial>
      <mass value="10"/>
      <inertia ixx="1.0" ixy="0.0" ixz="0.0" iyy="1.0" iyz="0.0" izz="1.0"/>
    </inertial>
  </link>
  <link name="right_front_wheel">
    <visual>
      <origin rpy="1.57075 0 0"/>
      <geometry>
        <cylinder length="0.1" radius="0.1"/>
      </geometry>
      <material name="blue"/>
    </visual>
    <collision>
      <origin rpy="1.57075 0 0"/>
      <geometry>
        <cylinder length="0.1" radius="0.1"/>
      </geometry>
    </collision>
    <inertial>
      <mass value="1"/>
      <inertia ixx="1.0" ixy="0.0" ixz="0.0" iyy="1.0" iyz="0.0" izz="1.0"/>
    </inertial>
  </link>
  <joint name="right_front_wheel_joint" type="continuous">
    <parent link="base_link"/>
    <child link="right_front_wheel"/>
    <axis xyz="0 1 0"/>
    <origin rpy="0 0 0 " xyz="0.40 0.5 0.1"/>
  </joint>
  <link name="left_front_wheel">
    <visual>
      <origin rpy="1.57075 0 0"/>
      <geometry>
        <cylinder length="0.1" radius="0.1"/>
      </geometry>
      <material name="blue"/>
    </visual>
    <collision>
      <origin rpy="1.57075 0 0"/>
      <geometry>
        <cylinder length="0.1" radius="0.1"/>
      </geometry>
    </collision>
    <inertial>
      <mass value="1"/>
      <inertia ixx="1.0" ixy="0.0" ixz="0.0" iyy="1.0" iyz="0.0" izz="1.0"/>
    </inertial>
  </link>
  <joint name="left_front_wheel_joint" type="continuous">
    <parent link="base_link"/>
    <child link="left_front_wheel"/>
    <axis xyz="0 1 0"/>
    <origin rpy="0 0 0" xyz="0.4 -0.5 0.1"/>
  </joint>
  <link name="right_back_wheel">
    <visual>
      <origin rpy="1.57075 0 0"/>
      <geometry>
        <cylinder length="0.1" radius="0.1"/>
      </geometry>
      <material name="blue"/>
    </visual>
    <collision>
      <origin rpy="1.57075 0 0"/>
      <geometry>
        <cylinder length="0.1" radius="0.1"/>
      </geometry>
    </collision>
    <inertial>
      <mass value="1"/>
      <inertia ixx="1.0" ixy="0.0" ixz="0.0" iyy="1.0" iyz="0.0" izz="1.0"/>
    </inertial>
  </link>
  <joint name="right_back_wheel_joint" type="continuous">
    <parent link="base_link"/>
    <child link="right_back_wheel"/>
    <axis xyz="0 1 0"/>
    <origin rpy="0 0 0" xyz="-0.4 0.5 0.1"/>
  </joint>
  <link name="left_back_wheel">
    <visual>
      <origin rpy="1.57075 0 0"/>
      <geometry>
        <cylinder length="0.1" radius="0.1"/>
      </geometry>
      <material name="blue"/>
    </visual>
    <collision>
      <origin rpy="1.57075 0 0"/>
      <geometry>
        <cylinder length="0.1" radius="0.1"/>
      </geometry>
    </collision>
    <inertial>
      <mass value="1"/>
      <inertia ixx="1.0" ixy="0.0" ixz="0.0" iyy="1.0" iyz="0.0" izz="1.0"/>
    </inertial>
  </link>
  <joint name="left_back_wheel_joint" type="continuous">
    <parent link="base_link"/>
    <child link="left_back_wheel"/>
    <!-- axis on which it will move -->
    <axis xyz="0 1 0"/>
    <origin rpy="0 0 0" xyz="-0.4 -0.5 0.1"/>
  </joint>
</robot>

