<?xml version="1.0"?>
<robot name="basic_robot">
<!-- For the color  -->
  <material name ="blue">
    <color rgba=" 0 0 0.8 1"/>
  </material>
<!-- Looks like it needed to be named base_link -->
  <link name="base_link">
    <visual>
    <!-- take out the xyz here -->
    <!-- <origin rpy=" 0 0 0" xyz="0 0 0.1"/> -->
    <origin rpy=" 0 0 0" xyz="0 0 0.1"/>/>
      <geometry>
        <!-- l x w x h -->
         <box size="1.0 1.0 0.1"/>
      </geometry>
    </visual>
    <collision>
      <origin rpy=" 0 0 0" xyz="0 0 0.1"/>/>
      <geometry>
         <box size="1.0 1.0 0.1"/>
      </geometry>
    </collision>
  </link>

  <link name="right_front_wheel">
    <visual>
    <!-- rpy looks like orientation of the object -->
      <!-- taking out the location below -->
      <!-- <origin rpy=" 1.57075 0 0" xyz="0 0 0.1 "/> -->
      <origin rpy=" 1.57075 0 0"/>
      <geometry>
        <cylinder length="0.1" radius="0.1"/>
      </geometry>
      <material name="blue"/>
    </visual>
    <collision>
      <origin rpy=" 1.57075 0 0"/>
      <geometry>
        <cylinder length="0.1" radius="0.1"/>
      </geometry>
    </collision>
  </link>

  <joint name="right_front_wheel_joint" type="continuous">
    <parent link="base_link" />
    <child link="right_front_wheel" />
    <!-- axis on which it will move -->
    <axis xyz="0 1 0"/>
    <!-- may need to replace the xyz here -->
    <!-- <origin rpy="0 0 0" xyz="0.40 0.5 0.0"/> -->
    <origin rpy="0 0 0 " xyz="0.40 0.5 0.1 "/>"
  </joint>

   <link name="left_front_wheel">
    <visual>
    <!-- rpy looks like orientation -->
    <!-- taking out the xyz here -->
      <origin rpy=" 1.57075 0 0"/>
      <geometry>
        <cylinder length="0.1" radius="0.1"/>
      </geometry>
      <material name="blue"/>
    </visual>
    <collision>
      <origin rpy=" 1.57075 0 0"/>
      <geometry>
        <cylinder length="0.1" radius="0.1"/>
      </geometry>
    </collision>
  </link>

  <joint name="left_front_wheel_joint" type="continuous">
    <parent link="base_link" />
    <child link="left_front_wheel" />
    <!-- axis on which it will move -->
    <axis xyz="0 1 0"/>
    <!-- adding the xyz from the wheel  back here  -->
    <!-- <origin rpy="0 0 0" xyz="0.4 -0.5 0.0"/> -->
    <origin rpy="0 0 0" xyz="0.4 -0.5 0.1"/>
  </joint>


  <link name="right_back_wheel">
    <visual>
    <!-- rpy looks like orientation -->
    <!-- take out the xyz here  -->
      <origin rpy=" 1.57075 0 0" />
      <geometry>
        <cylinder length="0.1" radius="0.1"/>
      </geometry>
      <material name="blue"/>
    </visual>
    <collision>
      <origin rpy=" 1.57075 0 0" />
      <geometry>
        <cylinder length="0.1" radius="0.1"/>
      </geometry>
    </collision>
  </link>

  <joint name="right_back_wheel_joint" type="continuous">
    <parent link="base_link" />
    <child link="right_back_wheel" />
    <!-- axis on which it will move -->
    <axis xyz="0 1 0"/>
    <!-- add the xyz from wheel back here -->
    <!-- <origin rpy="0 0 0" xyz="-0.4 0.5 0.0"/> -->
    <origin rpy="0 0 0" xyz="-0.4 0.5 0.1"/>
  </joint>

   <link name="left_back_wheel">
    <visual>
    <!-- rpy looks like orientation -->
    <!-- take out xyz here xyz here -->
      <origin rpy=" 1.57075 0 0"/>
      <geometry>
        <cylinder length="0.1" radius="0.1"/>
      </geometry>
      <material name="blue"/>
    </visual>
    <collision>
      <origin rpy=" 1.57075 0 0"/>
      <geometry>
        <cylinder length="0.1" radius="0.1"/>
      </geometry>
    </collision>
  </link>

  <joint name="left_back_wheel_joint" type="continuous">
    <parent link="base_link" />
    <child link="left_back_wheel" />
    <!-- axis on which it will move -->
    <axis xyz="0 1 0"/>
    <!-- add xyz from wheel here  -->
    <!-- <origin rpy="0 0 0" xyz="-0.4 -0.5 0.0"/> -->
    <origin rpy="0 0 0" xyz="-0.4 -0.5 0.1"/>
  </joint>
</robot>