<?xml version="1.0" ?>
<!-- =================================================================================== -->
<!-- |    This document was autogenerated by xacro from nasa_bot.xacro                 | -->
<!-- |    EDITING THIS FILE BY HAND IS NOT RECOMMENDED                                 | -->
<!-- =================================================================================== -->
<!-- Credit to https://github.com/ZBO-R8io/Roberto/blob/main/backups/lunarbot/urdf/lunarbot2.xacro -->
<!-- For the robot's urdf model -->
<!--Name of Robot-->
<robot name="Roberto_MkII">
  <!--Materials-->
  <material name="blue">
    <color rgba="0 0 0.8 1"/>
  </material>
  <material name="white">
    <color rgba="1 1 1 1"/>
  </material>
  <material name="black">
    <color rgba="0 0 0 1"/>
  </material>
  <material name="green">
    <color rgba="0 1 0 1"/>
  </material>
  <link name="base_link">
    <visual>
      <geometry>
        <mesh filename="package://lunarbot/meshes/base_link2.stl"/>
      </geometry>
      <material name="white"/>
    </visual>
    <collision>
      <geometry>
        <box size="1.5 0.8 0.3"/>
      </geometry>
    </collision>
    <inertial>
      <mass value="10"/>
      <inertia ixx="1.0" ixy="0" ixz="0" iyy="1.0" iyz="0" izz="1.0"/>
    </inertial>
  </link>
  <gazebo>
    <material>Gazebo/Grey</material>
  </gazebo>
  <link name="link_0">
    <visual>
      <geometry>
        <cylinder length="0.15" radius="0.3"/>
      </geometry>
      <origin rpy="1.57075 0 0"/>
      <material name="blue"/>
    </visual>
    <collision>
      <geometry>
        <cylinder length="0.15" radius="0.3"/>
      </geometry>
      <origin rpy="1.57075 0 0"/>
    </collision>
    <inertial>
      <mass value="5"/>
      <inertia ixx="1.0" ixy="0" ixz="0" iyy="1.0" iyz="0" izz="1.0"/>
    </inertial>
  </link>
  <joint name="joint_0" type="continuous">
    <parent link="base_link"/>
    <child link="link_0"/>
    <axis xyz="0 1 0"/>
    <origin xyz="0.6 0.475 -0.075"/>
  </joint>
  <transmission name="joint_0_wheel_trans">
    <type>transmission_interface/SimpleTransmission</type>
    <actuator name="joint_0_wheel_motor">
      <hardwareInterface>hardware_interface/VelocityJointInterface
        </hardwareInterface>
      <mechanicalReduction>1</mechanicalReduction>
    </actuator>
    <joint name="joint_0">
      <hardwareInterface>hardware_interface/VelocityJointInterface
        </hardwareInterface>
    </joint>
  </transmission>
  <gazebo reference="link_0">
    <mu1 value="200.0"/>
    <mu2 value="100.0"/>
    <kp value="10000000.0"/>
    <kd value="1.0"/>
    <material>Gazebo/Blue</material>
  </gazebo>
  <link name="link_1">
    <visual>
      <geometry>
        <cylinder length="0.15" radius="0.3"/>
      </geometry>
      <origin rpy="1.57075 0 0"/>
      <material name="blue"/>
    </visual>
    <collision>
      <geometry>
        <cylinder length="0.15" radius="0.3"/>
      </geometry>
      <origin rpy="1.57075 0 0"/>
    </collision>
    <inertial>
      <mass value="5"/>
      <inertia ixx="1.0" ixy="0" ixz="0" iyy="1.0" iyz="0" izz="1.0"/>
    </inertial>
  </link>
  <joint name="joint_1" type="continuous">
    <parent link="base_link"/>
    <child link="link_1"/>
    <axis xyz="0 1 0"/>
    <origin xyz="0.6 -0.475 -0.075"/>
  </joint>
  <transmission name="joint_1_wheel_trans">
    <type>transmission_interface/SimpleTransmission</type>
    <actuator name="joint_1_wheel_motor">
      <hardwareInterface>hardware_interface/VelocityJointInterface
        </hardwareInterface>
      <mechanicalReduction>1</mechanicalReduction>
    </actuator>
    <joint name="joint_1">
      <hardwareInterface>hardware_interface/VelocityJointInterface
        </hardwareInterface>
    </joint>
  </transmission>
  <gazebo reference="link_1">
    <mu1 value="200.0"/>
    <mu2 value="100.0"/>
    <kp value="10000000.0"/>
    <kd value="1.0"/>
    <material>Gazebo/Blue</material>
  </gazebo>
  <link name="link_2">
    <visual>
      <geometry>
        <cylinder length="0.15" radius="0.3"/>
      </geometry>
      <origin rpy="1.57075 0 0"/>
      <material name="blue"/>
    </visual>
    <collision>
      <geometry>
        <cylinder length="0.15" radius="0.3"/>
      </geometry>
      <origin rpy="1.57075 0 0"/>
    </collision>
    <inertial>
      <mass value="5"/>
      <inertia ixx="1.0" ixy="0" ixz="0" iyy="1.0" iyz="0" izz="1.0"/>
    </inertial>
  </link>
  <joint name="joint_2" type="continuous">
    <parent link="base_link"/>
    <child link="link_2"/>
    <axis xyz="0 1 0"/>
    <origin xyz="-0.6 0.475 -0.075"/>
  </joint>
  <transmission name="joint_2_wheel_trans">
    <type>transmission_interface/SimpleTransmission</type>
    <actuator name="joint_2_wheel_motor">
      <hardwareInterface>hardware_interface/VelocityJointInterface
        </hardwareInterface>
      <mechanicalReduction>1</mechanicalReduction>
    </actuator>
    <joint name="joint_2">
      <hardwareInterface>hardware_interface/VelocityJointInterface
        </hardwareInterface>
    </joint>
  </transmission>
  <gazebo reference="link_2">
    <mu1 value="200.0"/>
    <mu2 value="100.0"/>
    <kp value="10000000.0"/>
    <kd value="1.0"/>
    <material>Gazebo/Blue</material>
  </gazebo>
  <link name="link_3">
    <visual>
      <geometry>
        <cylinder length="0.15" radius="0.3"/>
      </geometry>
      <origin rpy="1.57075 0 0"/>
      <material name="blue"/>
    </visual>
    <collision>
      <geometry>
        <cylinder length="0.15" radius="0.3"/>
      </geometry>
      <origin rpy="1.57075 0 0"/>
    </collision>
    <inertial>
      <mass value="5"/>
      <inertia ixx="1.0" ixy="0" ixz="0" iyy="1.0" iyz="0" izz="1.0"/>
    </inertial>
  </link>
  <joint name="joint_3" type="continuous">
    <parent link="base_link"/>
    <child link="link_3"/>
    <axis xyz="0 1 0"/>
    <origin xyz="-0.6 -0.475 -0.075"/>
  </joint>
  <transmission name="joint_3_wheel_trans">
    <type>transmission_interface/SimpleTransmission</type>
    <actuator name="joint_3_wheel_motor">
      <hardwareInterface>hardware_interface/VelocityJointInterface
        </hardwareInterface>
      <mechanicalReduction>1</mechanicalReduction>
    </actuator>
    <joint name="joint_3">
      <hardwareInterface>hardware_interface/VelocityJointInterface
        </hardwareInterface>
    </joint>
  </transmission>
  <gazebo reference="link_3">
    <mu1 value="200.0"/>
    <mu2 value="100.0"/>
    <kp value="10000000.0"/>
    <kd value="1.0"/>
    <material>Gazebo/Blue</material>
  </gazebo>
  <link name="link_4">
    <visual>
      <geometry>
        <box size="0.05 0.1 0.8"/>
      </geometry>
      <origin xyz="0 0 0.3"/>
      <material name="green"/>
    </visual>
    <collision>
      <geometry>
        <box size="0.05 0.1 0.8"/>
      </geometry>
      <origin xyz="0 0 0.3"/>
    </collision>
    <inertial>
      <mass value="3"/>
      <inertia ixx="1.0" ixy="0" ixz="0" iyy="1.0" iyz="0" izz="1.0"/>
    </inertial>
  </link>
  <joint name="joint_4" type="fixed">
    <parent link="base_link"/>
    <child link="link_4"/>
    <origin rpy="0 -0.85 0" xyz="-0.25 0 -0.05"/>
  </joint>
  <gazebo reference="link_4">
    <material>Gazebo/Yellow</material>
  </gazebo>
  <link name="link_5">
    <visual>
      <geometry>
        <box size="0.1 0.1 0.3"/>
      </geometry>
      <origin rpy="0 1.575 0" xyz="0.15 0 0"/>
      <material name="blue"/>
    </visual>
    <collision>
      <geometry>
        <box size="0.1 0.1 0.3"/>
      </geometry>
      <origin rpy="0 1.575 0" xyz="0.15 0 0"/>
    </collision>
    <inertial>
      <mass value="2"/>
      <inertia ixx="1.0" ixy="0" ixz="0" iyy="1.0" iyz="0" izz="1.0"/>
    </inertial>
  </link>
  <joint name="joint_5" type="prismatic">
    <parent link="link_4"/>
    <child link="link_5"/>
    <axis xyz="0 0 1"/>
    <limit effort="1000" lower="-0.55" upper="0" velocity="0.5"/>
    <origin xyz="0 0 0.65"/>
  </joint>
  <transmission name="joint_5_trans">
    <type>transmission_interface/SimpleTransmission</type>
    <actuator name="joint_5_motor">
      <hardwareInterface>hardware_interface/PositionJointInterface
        </hardwareInterface>
      <mechanicalReduction>1</mechanicalReduction>
    </actuator>
    <joint name="joint_5">
      <hardwareInterface>hardware_interface/PositionJointInterface
        </hardwareInterface>
    </joint>
  </transmission>
  <gazebo reference="link_5">
    <mu1 value="200.0"/>
    <mu2 value="100.0"/>
    <kp value="10000000.0"/>
    <kd value="1.0"/>
    <material>Gazebo/Blue</material>
  </gazebo>
  <link name="auger_link">
    <visual>
      <origin xyz="0 0 -1.2"/>
      <geometry>
        <mesh filename="package://lunarbot/meshes/auger.stl"/>
      </geometry>
      <material name="black"/>
    </visual>
    <collision>
      <geometry>
        <cylinder length="0.4" radius="0.18"/>
      </geometry>
      <origin xyz="0 0 -0.4"/>
    </collision>
    <inertial>
      <mass value="5"/>
      <inertia ixx="1.0" ixy="0" ixz="0" iyy="1.0" iyz="0" izz="1.0"/>
    </inertial>
  </link>
  <joint name="auger_joint" type="continuous">
    <parent link="link_5"/>
    <child link="auger_link"/>
    <axis xyz="0 0 1"/>
    <origin xyz="0.23 0 0"/>
  </joint>
  <transmission name="auger_joint_trans">
    <type>transmission_interface/SimpleTransmission</type>
    <actuator name="auger_joint_motor">
      <hardwareInterface>hardware_interface/VelocityJointInterface
        </hardwareInterface>
      <mechanicalReduction>1</mechanicalReduction>
    </actuator>
    <joint name="auger_joint">
      <hardwareInterface>hardware_interface/VelocityJointInterface
        </hardwareInterface>
    </joint>
  </transmission>
  <gazebo reference="auger_link">
    <mu1 value="200.0"/>
    <mu2 value="100.0"/>
    <kp value="10000000.0"/>
    <kd value="1.0"/>
    <material>Gazebo/Black</material>
  </gazebo>
  <!--Gazebo plugin for ros_control-->
  <gazebo>
    <plugin filename="libgazebo_ros_control.so" name="gazebo_ros_control"/>
    <robotNamespace>/lunarbot</robotNamespace>
  </gazebo>
</robot>

